{"cells": [{"cell_type": "markdown", "metadata": {}, "source": ["<img src=\"../../images/banners/python-advanced.png\" width=\"600\"/>"]}, {"cell_type": "markdown", "id": "instructional-accused", "metadata": {}, "source": ["# <img src=\"../../images/logos/python.png\" width=\"23\"/> Error Handling (Exceptions) \n", "\n", "A Python program terminates as soon as it encounters an error. In Python, an error can be a syntax error or an exception.\n", "\n", "In this section, you will see what an exception is and how it differs from a syntax error. After that, you will learn about raising exceptions and making assertions. Then, you\u2019ll finish with a demonstration of the try and except block."]}, {"cell_type": "markdown", "metadata": {}, "source": ["## Table of Contents\n\n\n* [Exceptions versus Syntax Errors](#exceptions_versus_syntax_errors)\n* [Raising an Exception](#raising_an_exception)\n* [The `AssertionError` Exception](#the_`assertionerror`_exception)\n* [The `try` and `except` Block: Handling Exceptions](#the_`try`_and_`except`_block:_handling_exceptions)\n    * [The `except` Clause with No Exceptions](#the_`except`_clause_with_no_exceptions)\n    * [The `except` Clause with Multiple Exceptions](#the_`except`_clause_with_multiple_exceptions)\n* [The else Clause](#the_else_clause)\n* [Cleaning Up After Using `finally`](#cleaning_up_after_using_`finally`)\n* [List of Some Standard Exceptions](#list_of_some_standard_exceptions)\n* [Define Custom Exception](#define_custom_exception)\n    * [Creating Custom Exceptions](#creating_custom_exceptions)\n    * [Example: User-Defined Exception in Python](#example:_user-defined_exception_in_python)\n    * [Customizing Exception Classes](#customizing_exception_classes)\n* [Summary](#summary)\n* [References](#references)\n\n---"]}, {"cell_type": "markdown", "id": "secret-permit", "metadata": {}, "source": ["<a class=\"anchor\" id=\"exceptions_versus_syntax_errors\"></a>", "\n", "## Exceptions versus Syntax Errors\n", "\n", "Syntax errors occur when the parser detects an incorrect statement. Observe the following example:"]}, {"cell_type": "code", "execution_count": 8, "id": "answering-metadata", "metadata": {}, "outputs": [{"ename": "SyntaxError", "evalue": "invalid syntax (439779720.py, line 1)", "output_type": "error", "traceback": ["\u001b[0;36m  File \u001b[0;32m\"/var/folders/b4/tsp68dlx1gz9xlnpgbx21ytc0000gn/T/ipykernel_79930/439779720.py\"\u001b[0;36m, line \u001b[0;32m1\u001b[0m\n\u001b[0;31m    print(0 / 0))\u001b[0m\n\u001b[0m                ^\u001b[0m\n\u001b[0;31mSyntaxError\u001b[0m\u001b[0;31m:\u001b[0m invalid syntax\n"]}], "source": ["print(0 / 0))"]}, {"cell_type": "markdown", "id": "floppy-passion", "metadata": {}, "source": ["The arrow indicates where the parser ran into the syntax error. In this example, there was one bracket too many. Remove it and run your code again:"]}, {"cell_type": "code", "execution_count": 9, "id": "divine-senior", "metadata": {}, "outputs": [{"ename": "ZeroDivisionError", "evalue": "division by zero", "output_type": "error", "traceback": ["\u001b[0;31m---------------------------------------------------------------------------\u001b[0m", "\u001b[0;31mZeroDivisionError\u001b[0m                         Traceback (most recent call last)", "\u001b[0;32m/var/folders/b4/tsp68dlx1gz9xlnpgbx21ytc0000gn/T/ipykernel_79930/186921146.py\u001b[0m in \u001b[0;36m<module>\u001b[0;34m\u001b[0m\n\u001b[0;32m----> 1\u001b[0;31m \u001b[0mprint\u001b[0m\u001b[0;34m(\u001b[0m\u001b[0;36m10\u001b[0m \u001b[0;34m/\u001b[0m \u001b[0;36m0\u001b[0m\u001b[0;34m)\u001b[0m\u001b[0;34m\u001b[0m\u001b[0;34m\u001b[0m\u001b[0m\n\u001b[0m", "\u001b[0;31mZeroDivisionError\u001b[0m: division by zero"]}], "source": ["print(10 / 0)"]}, {"cell_type": "markdown", "id": "established-costume", "metadata": {}, "source": ["The arrow indicates where the parser ran into the syntax error. In this example, there was one bracket too many. Remove it and run your code again:"]}, {"cell_type": "markdown", "id": "tough-while", "metadata": {}, "source": ["Instead of showing the message exception `error`, Python details what type of exception error was encountered. In this case, it was a `ZeroDivisionError`. Python comes with various built-in exceptions as well as the possibility to create self-defined exceptions."]}, {"cell_type": "markdown", "id": "experienced-copying", "metadata": {}, "source": ["<a class=\"anchor\" id=\"raising_an_exception\"></a>", "\n", "## Raising an Exception\n", "\n", "We can use raise to throw an exception if a condition occurs. The statement can be complemented with a custom exception.\n", "\n", "If you want to throw an error when a certain condition occurs using raise, you could go about it like this:"]}, {"cell_type": "code", "execution_count": 25, "id": "93a58195-87d0-4805-b188-960909afacdf", "metadata": {}, "outputs": [{"ename": "Exception", "evalue": "X is not allowed to be greater that 5!", "output_type": "error", "traceback": ["\u001b[0;31m---------------------------------------------------------------------------\u001b[0m", "\u001b[0;31mException\u001b[0m                                 Traceback (most recent call last)", "\u001b[0;32m/var/folders/b4/tsp68dlx1gz9xlnpgbx21ytc0000gn/T/ipykernel_61944/4181305022.py\u001b[0m in \u001b[0;36m<module>\u001b[0;34m\u001b[0m\n\u001b[1;32m      1\u001b[0m \u001b[0mx\u001b[0m \u001b[0;34m=\u001b[0m \u001b[0;36m10\u001b[0m\u001b[0;34m\u001b[0m\u001b[0;34m\u001b[0m\u001b[0m\n\u001b[1;32m      2\u001b[0m \u001b[0;32mif\u001b[0m \u001b[0mx\u001b[0m \u001b[0;34m>\u001b[0m \u001b[0;36m5\u001b[0m\u001b[0;34m:\u001b[0m\u001b[0;34m\u001b[0m\u001b[0;34m\u001b[0m\u001b[0m\n\u001b[0;32m----> 3\u001b[0;31m     \u001b[0;32mraise\u001b[0m \u001b[0mException\u001b[0m\u001b[0;34m(\u001b[0m\u001b[0;34m\"X is not allowed to be greater that 5!\"\u001b[0m\u001b[0;34m)\u001b[0m\u001b[0;34m\u001b[0m\u001b[0;34m\u001b[0m\u001b[0m\n\u001b[0m", "\u001b[0;31mException\u001b[0m: X is not allowed to be greater that 5!"]}], "source": ["x = 10\n", "if x > 5:\n", "    raise Exception(\"X is not allowed to be greater that 5!\")"]}, {"cell_type": "code", "execution_count": 78, "id": "active-player", "metadata": {}, "outputs": [{"ename": "Exception", "evalue": "x should not exceed 5. The value of x was: 10", "output_type": "error", "traceback": ["\u001b[0;31m---------------------------------------------------------------------------\u001b[0m", "\u001b[0;31mException\u001b[0m                                 Traceback (most recent call last)", "\u001b[0;32m<ipython-input-78-6849d6299e06>\u001b[0m in \u001b[0;36m<module>\u001b[0;34m\u001b[0m\n\u001b[1;32m      1\u001b[0m \u001b[0mx\u001b[0m \u001b[0;34m=\u001b[0m \u001b[0;36m10\u001b[0m\u001b[0;34m\u001b[0m\u001b[0;34m\u001b[0m\u001b[0m\n\u001b[1;32m      2\u001b[0m \u001b[0;32mif\u001b[0m \u001b[0mx\u001b[0m \u001b[0;34m>\u001b[0m \u001b[0;36m5\u001b[0m\u001b[0;34m:\u001b[0m\u001b[0;34m\u001b[0m\u001b[0;34m\u001b[0m\u001b[0m\n\u001b[0;32m----> 3\u001b[0;31m     \u001b[0;32mraise\u001b[0m \u001b[0mException\u001b[0m\u001b[0;34m(\u001b[0m\u001b[0;34mf'x should not exceed 5. The value of x was: {x}'\u001b[0m\u001b[0;34m)\u001b[0m\u001b[0;34m\u001b[0m\u001b[0;34m\u001b[0m\u001b[0m\n\u001b[0m", "\u001b[0;31mException\u001b[0m: x should not exceed 5. The value of x was: 10"]}], "source": ["x = 10\n", "if x > 5:\n", "    raise Exception(f'x should not exceed 5. The value of x was: {x}')"]}, {"cell_type": "markdown", "id": "laughing-seller", "metadata": {}, "source": ["The program comes to a halt and displays our exception to screen, offering clues about what went wrong."]}, {"cell_type": "markdown", "id": "amazing-light", "metadata": {}, "source": ["<a class=\"anchor\" id=\"the_`assertionerror`_exception\"></a>", "\n", "## The `AssertionError` Exception"]}, {"cell_type": "code", "execution_count": 26, "id": "b812a8ab-7a79-4782-a2e7-7e9edacec394", "metadata": {}, "outputs": [], "source": ["x = 5"]}, {"cell_type": "code", "execution_count": 39, "id": "697e7625-c332-4f9f-9868-1101ac0c23e8", "metadata": {}, "outputs": [{"ename": "AssertionError", "evalue": "x should be equal to 4", "output_type": "error", "traceback": ["\u001b[0;31m---------------------------------------------------------------------------\u001b[0m", "\u001b[0;31mAssertionError\u001b[0m                            Traceback (most recent call last)", "\u001b[0;32m/var/folders/b4/tsp68dlx1gz9xlnpgbx21ytc0000gn/T/ipykernel_61944/2648026492.py\u001b[0m in \u001b[0;36m<module>\u001b[0;34m\u001b[0m\n\u001b[0;32m----> 1\u001b[0;31m \u001b[0;32massert\u001b[0m \u001b[0mx\u001b[0m \u001b[0;34m==\u001b[0m \u001b[0;36m4\u001b[0m\u001b[0;34m,\u001b[0m \u001b[0;34m\"x should be equal to 4\"\u001b[0m\u001b[0;34m\u001b[0m\u001b[0;34m\u001b[0m\u001b[0m\n\u001b[0m", "\u001b[0;31mAssertionError\u001b[0m: x should be equal to 4"]}], "source": ["assert x == 4, \"x should be equal to 4\""]}, {"cell_type": "markdown", "id": "active-moore", "metadata": {}, "source": ["Instead of waiting for a program to crash midway, you can also start by making an assertion in Python. We `assert` that a certain condition is met. If this condition turns out to be `True`, then that is excellent! The program can continue. If the condition turns out to be False, you can have the program throw an `AssertionError` exception.\n", "\n", "Have a look at the following example, where it is asserted that the code will be executed on a Linux system:"]}, {"cell_type": "code", "execution_count": 94, "id": "enabling-documentation", "metadata": {}, "outputs": [], "source": ["import sys\n", "assert 'linux' == sys.platform, \"This code runs on Linux only.\""]}, {"cell_type": "markdown", "id": "sublime-theology", "metadata": {}, "source": ["f you run this code on a Linux machine, the assertion passes. If you were to run this code on a Windows machine, the outcome of the assertion would be `False` and the result would be the following:\n", "\n", "```python\n", "Traceback (most recent call last):\n", "  File \"<input>\", line 2, in <module>\n", "AssertionError: This code runs on Linux only.\n", "```"]}, {"cell_type": "markdown", "id": "realistic-indicator", "metadata": {}, "source": ["In this example, throwing an AssertionError exception is the last thing that the program will do. The program will come to halt and will not continue. What if that is not what you want?"]}, {"cell_type": "markdown", "id": "magnetic-investigation", "metadata": {}, "source": ["<a class=\"anchor\" id=\"the_`try`_and_`except`_block:_handling_exceptions\"></a>", "\n", "## The `try` and `except` Block: Handling Exceptions\n", "\n", "The `try` and `except` block in Python is used to catch and handle `exceptions`. Python executes code following the try statement as a _normal_ part of the program. The code that follows the `except` statement is the program\u2019s response to any exceptions in the preceding `try` clause.\n", "\n", "<img src=\"../images/try-except.png\" alt=\"try-except.png\" width=300 align=\"left\" />"]}, {"cell_type": "markdown", "id": "psychological-budapest", "metadata": {}, "source": ["As you saw earlier, when syntactically correct code runs into an `error`, Python will throw an exception `error`. This exception error will crash the program if it is unhandled. The `except` clause determines how your program responds to exceptions.\n", "\n", "The following function can help you understand the `try` and `except` block:"]}, {"cell_type": "code", "execution_count": 47, "id": "resident-graduation", "metadata": {}, "outputs": [], "source": ["def linux_interaction():\n", "    assert ('linux' in sys.platform), \"Function can only run on Linux systems.\"\n", "    print('Doing something.')"]}, {"cell_type": "markdown", "id": "passive-dispatch", "metadata": {}, "source": ["The `linux_interaction()` can only run on a Linux system. The `assert` in this function will throw an `AssertionError` exception if you call it on an operating system other then Linux.\n", "\n", "You can give the function a `try` using the following code:"]}, {"cell_type": "code", "execution_count": 50, "id": "suburban-active", "metadata": {}, "outputs": [], "source": ["try:\n", "    linux_interaction()\n", "except:\n", "    pass"]}, {"cell_type": "markdown", "id": "atomic-better", "metadata": {}, "source": ["The way you handled the error here is by handing out a pass. If you were to run this code on a Windows machine, you would get nothing.\n", "\n", "The good thing here is that the program did not crash. But it would be nice to see if some type of exception occurred whenever you ran your code. To this end, you can change the `pass` into something that would generate an informative message, like so:"]}, {"cell_type": "code", "execution_count": 51, "id": "earlier-allah", "metadata": {}, "outputs": [{"name": "stdout", "output_type": "stream", "text": ["Linux function was not executed\n"]}], "source": ["try:\n", "    linux_interaction()\n", "except:\n", "    print('Linux function was not executed')"]}, {"cell_type": "markdown", "id": "british-unknown", "metadata": {}, "source": ["Execute this code on a Windows machine, you would get this as output:\n", "    \n", "```bash\n", "Linux function was not executed\n", "```"]}, {"cell_type": "markdown", "id": "suited-intranet", "metadata": {}, "source": ["When an exception occurs in a program running this function, the program will continue as well as inform you about the fact that the function call was not successful.\n", "\n", "What you did not get to see was the type of error that was thrown as a result of the function call. In order to see exactly what went wrong, you would need to catch the error that the function threw.\n", "\n", "The following code is an example where you capture the `AssertionError` and output that message to screen:"]}, {"cell_type": "code", "execution_count": 28, "id": "thrown-cartridge", "metadata": {}, "outputs": [{"name": "stdout", "output_type": "stream", "text": ["Doing something.\n"]}], "source": ["try:\n", "    linux_interaction()\n", "except AssertionError as error:\n", "    print(error)\n", "    print('The linux_interaction() function was not executed')"]}, {"cell_type": "markdown", "id": "norman-operator", "metadata": {}, "source": ["Running this function on a Windows machine outputs the following:\n", "    \n", "```bash\n", "Function can only run on Linux systems.\n", "The linux_interaction() function was not executed\n", "```"]}, {"cell_type": "markdown", "id": "reported-browse", "metadata": {}, "source": ["The first message is the `AssertionError`, informing you that the function can only be executed on a Linux machine. The second message tells you which function was not executed.\n", "\n", "In the previous example, you called a function that you wrote yourself. When you executed the function, you caught the AssertionError exception and printed it to screen."]}, {"cell_type": "markdown", "id": "lesser-point", "metadata": {}, "source": ["Here\u2019s another example where you open a file and use a built-in exception:"]}, {"cell_type": "code", "execution_count": 12, "id": "typical-technique", "metadata": {}, "outputs": [{"name": "stdout", "output_type": "stream", "text": ["Could not open file.log\n"]}], "source": ["try:\n", "    with open('file.log') as file:\n", "        read_data = file.read()\n", "except:\n", "    print('Could not open file.log')"]}, {"cell_type": "markdown", "id": "threatened-midwest", "metadata": {}, "source": ["If file.log does not exist, this block of code will output the following:\n", "\n", "```bash\n", "Could not open file.log\n", "```"]}, {"cell_type": "markdown", "id": "lesser-friendship", "metadata": {}, "source": ["This is an informative message, and our program will still continue to run. In the [Python docs](https://docs.python.org/3/library/exceptions.html), you can see that there are a lot of built-in exceptions that you can use here. One exception described on that page is the following:\n", "\n", "> Exception `FileNotFoundError`\n", "> \n", "> Raised when a file or directory is requested but doesn\u2019t exist. Corresponds to errno `ENOENT`.\n", "\n", "To catch this type of exception and print it to screen, you could use the following code:"]}, {"cell_type": "code", "execution_count": 65, "id": "continent-textbook", "metadata": {}, "outputs": [{"name": "stdout", "output_type": "stream", "text": ["[Errno 2] No such file or directory: 'file.log'\n"]}], "source": ["try:\n", "    with open('file.log') as file:\n", "        read_data = file.read()\n", "except FileNotFoundError as fnf_error:\n", "    print(fnf_error)"]}, {"cell_type": "markdown", "id": "cleared-corner", "metadata": {}, "source": ["In this case, if file.log does not exist, the output will be the following:\n", "\n", "```bash\n", "[Errno 2] No such file or directory: 'file.log'\n", "```"]}, {"cell_type": "markdown", "id": "victorian-grave", "metadata": {}, "source": ["You can have more than one function call in your `try` clause and anticipate catching various exceptions. A thing to note here is that the code in the `try` clause will stop as soon as an exception is encountered."]}, {"cell_type": "markdown", "id": "geological-package", "metadata": {}, "source": ["Look at the following code. Here, you first call the `linux_interaction()` function and then try to open a file"]}, {"cell_type": "code", "execution_count": 15, "id": "qualified-speed", "metadata": {}, "outputs": [{"name": "stdout", "output_type": "stream", "text": ["Doing something.\n", "[Errno 2] No such file or directory: 'file.log'\n"]}], "source": ["try:\n", "    linux_interaction()\n", "    with open('file.log') as file:\n", "        read_data = file.read()\n", "except FileNotFoundError as fnf_error:\n", "    print(fnf_error)\n", "except AssertionError as error:\n", "    print(error)\n", "    print('Linux linux_interaction() function was not executed')"]}, {"cell_type": "markdown", "id": "acknowledged-liver", "metadata": {}, "source": ["If the file does not exist, running this code on a Windows machine will output the following:\n", "\n", "```bash\n", "Function can only run on Linux systems.\n", "Linux linux_interaction() function was not executed\n", "```"]}, {"cell_type": "markdown", "id": "pharmaceutical-jumping", "metadata": {}, "source": ["Inside the `try` clause, you ran into an exception immediately and did not get to the part where you attempt to open `file.log`. Now look at what happens when you run the code on a Linux machine:\n", "\n", "```bash\n", "[Errno 2] No such file or directory: 'file.log'\n", "```"]}, {"cell_type": "markdown", "id": "introductory-trash", "metadata": {}, "source": ["Here are the key takeaways:\n", "\n", "- A `try` clause is executed up until the point where the first exception is encountered.\n", "- Inside the `except` clause, or the exception handler, you determine how the program responds to the exception.\n", "- You can anticipate multiple exceptions and differentiate how the program should respond to them.\n", "- Avoid using bare `except` clauses."]}, {"cell_type": "markdown", "id": "fancy-insured", "metadata": {}, "source": ["<a class=\"anchor\" id=\"the_`except`_clause_with_no_exceptions\"></a>", "\n", "### The `except` Clause with No Exceptions\n", "\n", "You can also use the except statement with no exceptions defined as follows:"]}, {"cell_type": "code", "execution_count": 25, "id": "hairy-trading", "metadata": {}, "outputs": [{"name": "stdout", "output_type": "stream", "text": ["unknown error\n"]}], "source": ["try:\n", "    with open('file.log') as file:\n", "        read_data = file.read()\n", "except:\n", "    print('unknown error')"]}, {"cell_type": "markdown", "id": "confirmed-adobe", "metadata": {}, "source": ["This kind of a try-except statement catches all the exceptions that occur. Using this kind of try-except statement is not considered a good programming practice though, because it catches all exceptions but does not make the programmer identify the root cause of the problem that may occur."]}, {"cell_type": "markdown", "id": "moderate-limitation", "metadata": {}, "source": ["**Warning:** Catching `Exception` hides all errors\u2026even those which are completely unexpected. This is why you should avoid bare `except` clauses in your Python programs. Instead, you\u2019ll want to refer to _specific exception classes_ you want to catch and handle. You can learn more about why this is a good idea in [this tutorial](https://realpython.com/the-most-diabolical-python-antipattern/)."]}, {"cell_type": "markdown", "id": "positive-parish", "metadata": {}, "source": ["<a class=\"anchor\" id=\"the_`except`_clause_with_multiple_exceptions\"></a>", "\n", "### The `except` Clause with Multiple Exceptions\n", "\n", "You can also use the same except statement to handle multiple exceptions as follows:"]}, {"cell_type": "code", "execution_count": 131, "id": "native-auction", "metadata": {}, "outputs": [{"name": "stdout", "output_type": "stream", "text": ["[Errno 2] No such file or directory: 'file.log'\n"]}], "source": ["try:\n", "    with open('file.log') as file:\n", "        read_data = file.read()\n", "except (FileNotFoundError, PermissionError) as e:\n", "    print(e)"]}, {"cell_type": "markdown", "id": "failing-anderson", "metadata": {}, "source": ["<a class=\"anchor\" id=\"the_else_clause\"></a>", "\n", "## The else Clause\n", "\n", "In Python, using the `else` statement, you can instruct a program to execute a certain block of code only in the absence of exceptions.\n", "\n", "<img src=\"../images/try-else.png\" alt=\"try-else.png\" width=300 align=\"left\" />"]}, {"cell_type": "markdown", "id": "sorted-senior", "metadata": {}, "source": ["Look at the following example:"]}, {"cell_type": "code", "execution_count": 17, "id": "another-metadata", "metadata": {}, "outputs": [{"name": "stdout", "output_type": "stream", "text": ["Doing something.\n", "Executing the else clause.\n"]}], "source": ["try:\n", "    linux_interaction()\n", "except AssertionError as error:\n", "    print(error)\n", "else:\n", "    print('Executing the else clause.')"]}, {"cell_type": "markdown", "id": "incredible-hughes", "metadata": {}, "source": ["If you were to run this code on a Linux system, the output would be the following:\n", "\n", "```bash\n", "Doing something.\n", "Executing the else clause.\n", "```"]}, {"cell_type": "markdown", "id": "quality-wisdom", "metadata": {}, "source": ["Because the program did not run into any exceptions, the `else` clause was executed.\n", "\n", "You can also try to run code inside the `else` clause and catch possible exceptions there as well:"]}, {"cell_type": "code", "execution_count": 18, "id": "alive-marshall", "metadata": {}, "outputs": [{"name": "stdout", "output_type": "stream", "text": ["Doing something.\n", "[Errno 2] No such file or directory: 'file.log'\n"]}], "source": ["try:\n", "    linux_interaction()\n", "except AssertionError as error:\n", "    print(error)\n", "else:\n", "    try:\n", "        with open('file.log') as file:\n", "            read_data = file.read()\n", "    except FileNotFoundError as fnf_error:\n", "        print(fnf_error)"]}, {"cell_type": "markdown", "id": "little-distribution", "metadata": {}, "source": ["If you were to execute this code on a Linux machine, you would get the following result:\n", "\n", "```bash\n", "Doing something.\n", "[Errno 2] No such file or directory: 'file.log'\n", "```"]}, {"cell_type": "markdown", "id": "shaped-hypothetical", "metadata": {}, "source": ["From the output, you can see that the `linux_interaction()` function ran. Because no exceptions were encountered, an attempt to open `file.log` was made. That file did not exist, and instead of opening the file, you caught the `FileNotFoundError` exception."]}, {"cell_type": "markdown", "id": "express-clinic", "metadata": {}, "source": ["<a class=\"anchor\" id=\"cleaning_up_after_using_`finally`\"></a>", "\n", "## Cleaning Up After Using `finally`\n", "\n", "Imagine that you always had to implement some sort of action to clean up after executing your code. Python enables you to do so using the finally clause.\n", "\n", "<img src=\"../images/try-finally.png\" alt=\"try-finally.png\" width=300 align=\"left\" />"]}, {"cell_type": "markdown", "id": "smooth-behavior", "metadata": {}, "source": ["Have a look at the following example:"]}, {"cell_type": "code", "execution_count": 141, "id": "derived-disorder", "metadata": {}, "outputs": [{"name": "stdout", "output_type": "stream", "text": ["Doing something.\n", "[Errno 2] No such file or directory: 'file.log'\n", "Cleaning up, irrespective of any exceptions.\n"]}], "source": ["try:\n", "    linux_interaction()\n", "except AssertionError as error:\n", "    print(error)\n", "else:\n", "    try:\n", "        with open('file.log') as file:\n", "            read_data = file.read()\n", "    except FileNotFoundError as fnf_error:\n", "        print(fnf_error)\n", "finally:\n", "    print('Cleaning up, irrespective of any exceptions.')"]}, {"cell_type": "markdown", "id": "controlled-fundamental", "metadata": {}, "source": ["In the previous code, everything in the finally clause will be executed. It does not matter if you encounter an exception somewhere in the `try` or `else` clauses. Running the previous code on a Windows machine would output the following:\n", "\n", "```bash\n", "Function can only run on Linux systems.\n", "Cleaning up, irrespective of any exceptions.\n", "```"]}, {"cell_type": "markdown", "id": "abroad-phase", "metadata": {}, "source": ["<a class=\"anchor\" id=\"list_of_some_standard_exceptions\"></a>", "\n", "## List of Some Standard Exceptions"]}, {"cell_type": "markdown", "id": "serial-climb", "metadata": {}, "source": ["|Exception|Description|\n", "|:--|:--|\n", "|`Exception`|Base class for all exceptions|\n", "|`StopIteration`|Raised when the `next()` method of an iterator does not point to any object.|\n", "|`SystemExit`|Raised by the `sys.exit()` function.|\n", "|`StandardError`|Base class for all built-in exceptions except `StopIteration` and `SystemExit`.|\n", "|`ArithmeticError`|Base class for all errors that occur for numeric calculation.|\n", "|`OverflowError`|Raised when a calculation exceeds maximum limit for a numeric type.|\n", "|`FloatingPointError`|Raised when a floating point calculation fails.|\n", "|`ZeroDivisionError`|Raised when division or module by zero takes place for all numeric types.|\n", "|`AssertionError`|Raised in case of failure of the Assert statement.|\n", "|`AttributeError`|Raised in case of failure of attribute reference or assignment.|\n", "|`EOFError`|Raised when there is no input from either the `raw_input()` or `input()` function and the end of file is reached.|\n", "|`ImportError`|Raised when an import statement fails.|\n", "|`KeyboardInterrupt`|Raised when the user interrupts program execution, usually by pressing `Ctrl+c`.|\n", "|`LookupError`|Base class for all lookup errors.|\n", "|`IndexError`|Raised when an index is not found in a sequence.|\n", "|`KeyError`|Raised when the specified key is not found in the dictionary.|\n", "|`NameError`|Raised when an identifier is not found in the local or global namespace.|\n", "|`UnboundLocalError`|Raised when trying to access a local variable in a function or method but no value has been assigned to it.|\n", "|`EnvironmentError`|Base class for all exceptions that occur outside the Python environment.|\n", "|`IOError`|Raised when an input/ output operation fails, such as the print statement or the `open()` function when trying to open a file that does not exist.|\n", "|`IOError`|Raised for operating system-related errors.|\n", "|`SyntaxError`|Raised when there is an error in Python syntax.|\n", "|`IndentationError`|Raised when indentation is not specified properly.|\n", "|`SystemError`|Raised when the interpreter finds an internal problem, but when this error is encountered the Python interpreter does not exit.|\n", "|`SystemExit`|Raised when Python interpreter is quit by using the `sys.exit()` function. If not handled in the code, causes the interpreter to exit.|\n", "|`TypeError`|Raised when an operation or function is attempted that is invalid for the specified data type.|\n", "|`ValueError`|Raised when the built-in function for a data type has the valid type of arguments, but the arguments have invalid values specified.|\n", "|`RuntimeError`|Raised when a generated error does not fall into any category.|\n", "|`NotImplementedError`|Raised when an abstract method that needs to be implemented in an inherited class is not actually implemented.|"]}, {"cell_type": "markdown", "id": "catholic-carnival", "metadata": {}, "source": ["<a class=\"anchor\" id=\"define_custom_exception\"></a>", "\n", "## Define Custom Exception\n", "\n", "Python has numerous built-in exceptions that force your program to output an error when something in the program goes wrong.\n", "\n", "However, sometimes you may need to create your own custom exceptions that serve your purpose."]}, {"cell_type": "markdown", "id": "vertical-nicaragua", "metadata": {}, "source": ["<a class=\"anchor\" id=\"creating_custom_exceptions\"></a>", "\n", "### Creating Custom Exceptions\n", "\n", "In Python, users can define custom exceptions by creating a new class. This exception class has to be derived, either directly or indirectly, from the built-in `Exception` class. Most of the built-in exceptions are also derived from this class."]}, {"cell_type": "code", "execution_count": 103, "id": "virtual-luther", "metadata": {}, "outputs": [], "source": ["class CustomError(Exception):\n", "    pass"]}, {"cell_type": "markdown", "id": "killing-microphone", "metadata": {}, "source": ["Here, we have created a user-defined exception called `CustomError` which inherits from the `Exception` class. This new exception, like other exceptions, can be raised using the `raise` statement with an optional error message."]}, {"cell_type": "code", "execution_count": 104, "id": "adjustable-module", "metadata": {}, "outputs": [{"ename": "CustomError", "evalue": "", "output_type": "error", "traceback": ["\u001b[0;31m---------------------------------------------------------------------------\u001b[0m", "\u001b[0;31mCustomError\u001b[0m                               Traceback (most recent call last)", "\u001b[0;32m/var/folders/b4/tsp68dlx1gz9xlnpgbx21ytc0000gn/T/ipykernel_61944/571119069.py\u001b[0m in \u001b[0;36m<module>\u001b[0;34m\u001b[0m\n\u001b[0;32m----> 1\u001b[0;31m \u001b[0;32mraise\u001b[0m \u001b[0mCustomError\u001b[0m\u001b[0;34m\u001b[0m\u001b[0;34m\u001b[0m\u001b[0m\n\u001b[0m", "\u001b[0;31mCustomError\u001b[0m: "]}], "source": ["raise CustomError"]}, {"cell_type": "code", "execution_count": 105, "id": "stretch-withdrawal", "metadata": {}, "outputs": [{"ename": "CustomError", "evalue": "An error occurred", "output_type": "error", "traceback": ["\u001b[0;31m---------------------------------------------------------------------------\u001b[0m", "\u001b[0;31mCustomError\u001b[0m                               Traceback (most recent call last)", "\u001b[0;32m/var/folders/b4/tsp68dlx1gz9xlnpgbx21ytc0000gn/T/ipykernel_61944/4012702173.py\u001b[0m in \u001b[0;36m<module>\u001b[0;34m\u001b[0m\n\u001b[0;32m----> 1\u001b[0;31m \u001b[0;32mraise\u001b[0m \u001b[0mCustomError\u001b[0m\u001b[0;34m(\u001b[0m\u001b[0;34m\"An error occurred\"\u001b[0m\u001b[0;34m)\u001b[0m\u001b[0;34m\u001b[0m\u001b[0;34m\u001b[0m\u001b[0m\n\u001b[0m", "\u001b[0;31mCustomError\u001b[0m: An error occurred"]}], "source": ["raise CustomError(\"An error occurred\")"]}, {"cell_type": "markdown", "id": "rising-facility", "metadata": {}, "source": ["When we are developing a large Python program, it is a good practice to place all the user-defined exceptions that our program raises in a separate file. Many standard modules do this. They define their exceptions separately as `exceptions.py` or `errors.py` (generally but not always). Look [here](https://github.com/RasaHQ/rasa/blob/main/rasa/shared/exceptions.py) for a real example."]}, {"cell_type": "markdown", "id": "hearing-convergence", "metadata": {}, "source": ["User-defined exception class can implement everything a normal class can do, but we generally make them simple and concise. Most implementations declare a custom base class and derive others exception classes from this base class. This concept is made clearer in the following example."]}, {"cell_type": "markdown", "id": "wound-proof", "metadata": {}, "source": ["<a class=\"anchor\" id=\"example:_user-defined_exception_in_python\"></a>", "\n", "### Example: User-Defined Exception in Python\n", "\n", "In this example, we will illustrate how user-defined exceptions can be used in a program to raise and catch errors."]}, {"cell_type": "markdown", "id": "further-breath", "metadata": {}, "source": ["This program will ask the user to enter a number until they guess a stored number correctly. To help them figure it out, a hint is provided whether their guess is greater than or less than the stored number"]}, {"cell_type": "code", "execution_count": 17, "id": "adaptive-birthday", "metadata": {}, "outputs": [], "source": ["# define Python user-defined exceptions\n", "class Error(Exception):\n", "    \"\"\"Base class for other exceptions\"\"\"\n", "\n", "class ValueTooSmallError(Error):\n", "    \"\"\"Raised when the input value is too small\"\"\"\n", "\n", "class ValueTooLargeError(Error):\n", "    \"\"\"Raised when the input value is too large\"\"\""]}, {"cell_type": "code", "execution_count": null, "id": "median-bridal", "metadata": {}, "outputs": [], "source": ["# you need to guess this number\n", "number = 10\n", "\n", "# user guesses a number until he/she gets it right\n", "while True:\n", "    try:\n", "        i_num = int(input(\"Enter a number: \"))\n", "        if i_num < number:\n", "            raise ValueTooSmallError\n", "        elif i_num > number:\n", "            raise ValueTooLargeError\n", "        break\n", "    except ValueTooSmallError:\n", "        print(\"This value is too small, try again!\")\n", "        print()\n", "    except ValueTooLargeError:\n", "        print(\"This value is too large, try again!\")\n", "        print()\n", "\n", "print(\"Congratulations! You guessed it correctly.\")"]}, {"cell_type": "markdown", "id": "unauthorized-generic", "metadata": {}, "source": ["We have defined a base class called `Error`.\n", "\n", "The other two exceptions (`ValueTooSmallError` and `ValueTooLargeError`) that are actually raised by our program are derived from this class. This is the standard way to define user-defined exceptions in Python programming, but you are not limited to this way only."]}, {"cell_type": "markdown", "id": "cellular-twelve", "metadata": {}, "source": ["<a class=\"anchor\" id=\"customizing_exception_classes\"></a>", "\n", "### Customizing Exception Classes\n", "\n", "We can further customize this class to accept other arguments as per our needs."]}, {"cell_type": "code", "execution_count": 157, "id": "early-distinction", "metadata": {}, "outputs": [], "source": ["class SalaryNotInRangeError(Exception):\n", "    \"\"\"Exception raised for errors in the input salary.\n", "\n", "    Attributes:\n", "        salary -- input salary which caused the error\n", "        message -- explanation of the error\n", "    \"\"\"\n", "\n", "    def __init__(self, salary, message=\"Salary is not in (5000, 15000) range\"):\n", "        self.salary = salary\n", "        self.message = message\n", "        super().__init__(self.message)"]}, {"cell_type": "code", "execution_count": 158, "id": "acute-idaho", "metadata": {}, "outputs": [{"name": "stdout", "output_type": "stream", "text": ["Enter salary amount: 1000\n"]}, {"ename": "SalaryNotInRangeError", "evalue": "Salary is not in (5000, 15000) range", "output_type": "error", "traceback": ["\u001b[0;31m---------------------------------------------------------------------------\u001b[0m", "\u001b[0;31mSalaryNotInRangeError\u001b[0m                     Traceback (most recent call last)", "\u001b[0;32m<ipython-input-158-69fb9589daca>\u001b[0m in \u001b[0;36m<module>\u001b[0;34m\u001b[0m\n\u001b[1;32m      1\u001b[0m \u001b[0msalary\u001b[0m \u001b[0;34m=\u001b[0m \u001b[0mint\u001b[0m\u001b[0;34m(\u001b[0m\u001b[0minput\u001b[0m\u001b[0;34m(\u001b[0m\u001b[0;34m\"Enter salary amount: \"\u001b[0m\u001b[0;34m)\u001b[0m\u001b[0;34m)\u001b[0m\u001b[0;34m\u001b[0m\u001b[0;34m\u001b[0m\u001b[0m\n\u001b[1;32m      2\u001b[0m \u001b[0;32mif\u001b[0m \u001b[0;32mnot\u001b[0m \u001b[0;36m5000\u001b[0m \u001b[0;34m<\u001b[0m \u001b[0msalary\u001b[0m \u001b[0;34m<\u001b[0m \u001b[0;36m15000\u001b[0m\u001b[0;34m:\u001b[0m\u001b[0;34m\u001b[0m\u001b[0;34m\u001b[0m\u001b[0m\n\u001b[0;32m----> 3\u001b[0;31m     \u001b[0;32mraise\u001b[0m \u001b[0mSalaryNotInRangeError\u001b[0m\u001b[0;34m(\u001b[0m\u001b[0msalary\u001b[0m\u001b[0;34m)\u001b[0m\u001b[0;34m\u001b[0m\u001b[0;34m\u001b[0m\u001b[0m\n\u001b[0m", "\u001b[0;31mSalaryNotInRangeError\u001b[0m: Salary is not in (5000, 15000) range"]}], "source": ["salary = int(input(\"Enter salary amount: \"))\n", "if not 5000 < salary < 15000:\n", "    raise SalaryNotInRangeError(salary)"]}, {"cell_type": "markdown", "id": "quick-information", "metadata": {}, "source": ["Here, we have overridden the constructor of the `Exception` class to accept our own custom arguments `salary` and `message`. Then, the constructor of the parent `Exception` class is called manually with the `self.message` argument using `super()`."]}, {"cell_type": "markdown", "id": "periodic-methodology", "metadata": {}, "source": ["The inherited `__str__` method of the Exception class is then used to display the corresponding message when `SalaryNotInRangeError` is raised. We can also customize the `__str__` method itself by overriding it."]}, {"cell_type": "code", "execution_count": 167, "id": "ready-diabetes", "metadata": {}, "outputs": [], "source": ["class SalaryNotInRangeError(Exception):\n", "    \"\"\"Exception raised for errors in the input salary.\n", "\n", "    Attributes:\n", "        salary -- input salary which caused the error\n", "        message -- explanation of the error\n", "    \"\"\"\n", "\n", "    def __init__(self, salary, message=\"Salary is not in (5000, 15000) range\"):\n", "        self.salary = salary\n", "        self.message = message\n", "        super().__init__(self.message)\n", "\n", "    def __str__(self):\n", "        return f'{self.salary} -> {self.message}'"]}, {"cell_type": "code", "execution_count": 168, "id": "associate-attendance", "metadata": {}, "outputs": [{"name": "stdout", "output_type": "stream", "text": ["Enter salary amount: 1000\n"]}, {"ename": "SalaryNotInRangeError", "evalue": "1000 -> Salary is not in (5000, 15000) range", "output_type": "error", "traceback": ["\u001b[0;31m---------------------------------------------------------------------------\u001b[0m", "\u001b[0;31mSalaryNotInRangeError\u001b[0m                     Traceback (most recent call last)", "\u001b[0;32m<ipython-input-168-69fb9589daca>\u001b[0m in \u001b[0;36m<module>\u001b[0;34m\u001b[0m\n\u001b[1;32m      1\u001b[0m \u001b[0msalary\u001b[0m \u001b[0;34m=\u001b[0m \u001b[0mint\u001b[0m\u001b[0;34m(\u001b[0m\u001b[0minput\u001b[0m\u001b[0;34m(\u001b[0m\u001b[0;34m\"Enter salary amount: \"\u001b[0m\u001b[0;34m)\u001b[0m\u001b[0;34m)\u001b[0m\u001b[0;34m\u001b[0m\u001b[0;34m\u001b[0m\u001b[0m\n\u001b[1;32m      2\u001b[0m \u001b[0;32mif\u001b[0m \u001b[0;32mnot\u001b[0m \u001b[0;36m5000\u001b[0m \u001b[0;34m<\u001b[0m \u001b[0msalary\u001b[0m \u001b[0;34m<\u001b[0m \u001b[0;36m15000\u001b[0m\u001b[0;34m:\u001b[0m\u001b[0;34m\u001b[0m\u001b[0;34m\u001b[0m\u001b[0m\n\u001b[0;32m----> 3\u001b[0;31m     \u001b[0;32mraise\u001b[0m \u001b[0mSalaryNotInRangeError\u001b[0m\u001b[0;34m(\u001b[0m\u001b[0msalary\u001b[0m\u001b[0;34m)\u001b[0m\u001b[0;34m\u001b[0m\u001b[0;34m\u001b[0m\u001b[0m\n\u001b[0m", "\u001b[0;31mSalaryNotInRangeError\u001b[0m: 1000 -> Salary is not in (5000, 15000) range"]}], "source": ["salary = int(input(\"Enter salary amount: \"))\n", "if not 5000 < salary < 15000:\n", "    raise SalaryNotInRangeError(salary)"]}, {"cell_type": "markdown", "id": "indian-christopher", "metadata": {}, "source": ["<a class=\"anchor\" id=\"summary\"></a>", "\n", "## Summary\n", "\n", "- `raise` allows you to throw an exception at any time.\n", "- `assert` enables you to verify if a certain condition is met and throw an exception if it isn\u2019t.\n", "- In the try clause, all statements are executed until an exception is encountered.\n", "- `except` is used to catch and handle the `exception(s)` that are encountered in the `try` clause.\n", "- `else` lets you code sections that should run only when no exceptions are encountered in the try clause.\n", "- `finally` enables you to execute sections of code that should always run, with or without any previously encountered exceptions.\n", "- Custom exceptions are implemented by inheriting from `Exception` base class."]}, {"cell_type": "markdown", "id": "prescription-bidding", "metadata": {}, "source": ["<a class=\"anchor\" id=\"references\"></a>", "\n", "## References\n", "- https://realpython.com/python-exceptions/\n", "- https://www.programiz.com/python-programming/user-defined-exception"]}], "metadata": {"kernelspec": {"display_name": "Python 3 (ipykernel)", "language": "python", "name": "python3"}, "language_info": {"codemirror_mode": {"name": "ipython", "version": 3}, "file_extension": ".py", "mimetype": "text/x-python", "name": "python", "nbconvert_exporter": "python", "pygments_lexer": "ipython3", "version": "3.7.10"}}, "nbformat": 4, "nbformat_minor": 5}